Workbook

Sheet By Section
A1: moveEZ (ID 2026-64): reviewer comments organized by section of the submitted paper
A2: All counts are formulas that read the All Comments sheet.
A4: Paper section | B4: Reviewer 4 | C4: Reviewer 5 | D4: Total | E4: Major | F4: Package change | G4: Not done
A5: Whole paper | B5: =COUNTIFS('All Comments'!$D:$D,$A5,'All Comments'!$B:$B,"Reviewer 4") -> 1 | C5: =COUNTIFS('All Comments'!$D:$D,$A5,'All Comments'!$B:$B,"Reviewer 5") -> 1 | D5: =B5+C5 -> 2 | E5: =COUNTIFS('All Comments'!$D:$D,$A5,'All Comments'!$G:$G,"Major") -> 2 | F5: =COUNTIFS('All Comments'!$D:$D,$A5,'All Comments'!$M:$M,"Yes") -> 0 | G5: =D5-COUNTIFS('All Comments'!$D:$D,$A5,'All Comments'!$P:$P,"Done")-COUNTIFS('All Comments'!$D:$D,$A5,'All Comments'!$P:$P,"Will not change") -> 2
A6: 1 Introduction | B6: =COUNTIFS('All Comments'!$D:$D,$A6,'All Comments'!$B:$B,"Reviewer 4") -> 0 | C6: =COUNTIFS('All Comments'!$D:$D,$A6,'All Comments'!$B:$B,"Reviewer 5") -> 4 | D6: =B6+C6 -> 4 | E6: =COUNTIFS('All Comments'!$D:$D,$A6,'All Comments'!$G:$G,"Major") -> 3 | F6: =COUNTIFS('All Comments'!$D:$D,$A6,'All Comments'!$M:$M,"Yes") -> 0 | G6: =D6-COUNTIFS('All Comments'!$D:$D,$A6,'All Comments'!$P:$P,"Done")-COUNTIFS('All Comments'!$D:$D,$A6,'All Comments'!$P:$P,"Will not change") -> 4
A7: 2 PCA Biplots | B7: =COUNTIFS('All Comments'!$D:$D,$A7,'All Comments'!$B:$B,"Reviewer 4") -> 0 | C7: =COUNTIFS('All Comments'!$D:$D,$A7,'All Comments'!$B:$B,"Reviewer 5") -> 1 | D7: =B7+C7 -> 1 | E7: =COUNTIFS('All Comments'!$D:$D,$A7,'All Comments'!$G:$G,"Major") -> 1 | F7: =COUNTIFS('All Comments'!$D:$D,$A7,'All Comments'!$M:$M,"Yes") -> 0 | G7: =D7-COUNTIFS('All Comments'!$D:$D,$A7,'All Comments'!$P:$P,"Done")-COUNTIFS('All Comments'!$D:$D,$A7,'All Comments'!$P:$P,"Will not change") -> 1
A8: 3 The moveEZ framework | B8: =COUNTIFS('All Comments'!$D:$D,$A8,'All Comments'!$B:$B,"Reviewer 4") -> 1 | C8: =COUNTIFS('All Comments'!$D:$D,$A8,'All Comments'!$B:$B,"Reviewer 5") -> 2 | D8: =B8+C8 -> 3 | E8: =COUNTIFS('All Comments'!$D:$D,$A8,'All Comments'!$G:$G,"Major") -> 0 | F8: =COUNTIFS('All Comments'!$D:$D,$A8,'All Comments'!$M:$M,"Yes") -> 2 | G8: =D8-COUNTIFS('All Comments'!$D:$D,$A8,'All Comments'!$P:$P,"Done")-COUNTIFS('All Comments'!$D:$D,$A8,'All Comments'!$P:$P,"Will not change") -> 3
A9: 4 Fixed variable frame | B9: =COUNTIFS('All Comments'!$D:$D,$A9,'All Comments'!$B:$B,"Reviewer 4") -> 1 | C9: =COUNTIFS('All Comments'!$D:$D,$A9,'All Comments'!$B:$B,"Reviewer 5") -> 6 | D9: =B9+C9 -> 7 | E9: =COUNTIFS('All Comments'!$D:$D,$A9,'All Comments'!$G:$G,"Major") -> 3 | F9: =COUNTIFS('All Comments'!$D:$D,$A9,'All Comments'!$M:$M,"Yes") -> 1 | G9: =D9-COUNTIFS('All Comments'!$D:$D,$A9,'All Comments'!$P:$P,"Done")-COUNTIFS('All Comments'!$D:$D,$A9,'All Comments'!$P:$P,"Will not change") -> 7
A10: 5 Dynamic frame | B10: =COUNTIFS('All Comments'!$D:$D,$A10,'All Comments'!$B:$B,"Reviewer 4") -> 0 | C10: =COUNTIFS('All Comments'!$D:$D,$A10,'All Comments'!$B:$B,"Reviewer 5") -> 4 | D10: =B10+C10 -> 4 | E10: =COUNTIFS('All Comments'!$D:$D,$A10,'All Comments'!$G:$G,"Major") -> 4 | F10: =COUNTIFS('All Comments'!$D:$D,$A10,'All Comments'!$M:$M,"Yes") -> 0 | G10: =D10-COUNTIFS('All Comments'!$D:$D,$A10,'All Comments'!$P:$P,"Done")-COUNTIFS('All Comments'!$D:$D,$A10,'All Comments'!$P:$P,"Will not change") -> 4
A11: 6 Automated alignment | B11: =COUNTIFS('All Comments'!$D:$D,$A11,'All Comments'!$B:$B,"Reviewer 4") -> 4 | C11: =COUNTIFS('All Comments'!$D:$D,$A11,'All Comments'!$B:$B,"Reviewer 5") -> 4 | D11: =B11+C11 -> 8 | E11: =COUNTIFS('All Comments'!$D:$D,$A11,'All Comments'!$G:$G,"Major") -> 7 | F11: =COUNTIFS('All Comments'!$D:$D,$A11,'All Comments'!$M:$M,"Yes") -> 1 | G11: =D11-COUNTIFS('All Comments'!$D:$D,$A11,'All Comments'!$P:$P,"Done")-COUNTIFS('All Comments'!$D:$D,$A11,'All Comments'!$P:$P,"Will not change") -> 8
A12: 7 Evaluation | B12: =COUNTIFS('All Comments'!$D:$D,$A12,'All Comments'!$B:$B,"Reviewer 4") -> 1 | C12: =COUNTIFS('All Comments'!$D:$D,$A12,'All Comments'!$B:$B,"Reviewer 5") -> 2 | D12: =B12+C12 -> 3 | E12: =COUNTIFS('All Comments'!$D:$D,$A12,'All Comments'!$G:$G,"Major") -> 1 | F12: =COUNTIFS('All Comments'!$D:$D,$A12,'All Comments'!$M:$M,"Yes") -> 2 | G12: =D12-COUNTIFS('All Comments'!$D:$D,$A12,'All Comments'!$P:$P,"Done")-COUNTIFS('All Comments'!$D:$D,$A12,'All Comments'!$P:$P,"Will not change") -> 3
A13: 8 Conclusion | B13: =COUNTIFS('All Comments'!$D:$D,$A13,'All Comments'!$B:$B,"Reviewer 4") -> 0 | C13: =COUNTIFS('All Comments'!$D:$D,$A13,'All Comments'!$B:$B,"Reviewer 5") -> 0 | D13: =B13+C13 -> 0 | E13: =COUNTIFS('All Comments'!$D:$D,$A13,'All Comments'!$G:$G,"Major") -> 0 | F13: =COUNTIFS('All Comments'!$D:$D,$A13,'All Comments'!$M:$M,"Yes") -> 0 | G13: =D13-COUNTIFS('All Comments'!$D:$D,$A13,'All Comments'!$P:$P,"Done")-COUNTIFS('All Comments'!$D:$D,$A13,'All Comments'!$P:$P,"Will not change") -> 0
A14: 10 References | B14: =COUNTIFS('All Comments'!$D:$D,$A14,'All Comments'!$B:$B,"Reviewer 4") -> 0 | C14: =COUNTIFS('All Comments'!$D:$D,$A14,'All Comments'!$B:$B,"Reviewer 5") -> 1 | D14: =B14+C14 -> 1 | E14: =COUNTIFS('All Comments'!$D:$D,$A14,'All Comments'!$G:$G,"Major") -> 0 | F14: =COUNTIFS('All Comments'!$D:$D,$A14,'All Comments'!$M:$M,"Yes") -> 0 | G14: =D14-COUNTIFS('All Comments'!$D:$D,$A14,'All Comments'!$P:$P,"Done")-COUNTIFS('All Comments'!$D:$D,$A14,'All Comments'!$P:$P,"Will not change") -> 1
A15: Package code | B15: =COUNTIFS('All Comments'!$D:$D,$A15,'All Comments'!$B:$B,"Reviewer 4") -> 2 | C15: =COUNTIFS('All Comments'!$D:$D,$A15,'All Comments'!$B:$B,"Reviewer 5") -> 10 | D15: =B15+C15 -> 12 | E15: =COUNTIFS('All Comments'!$D:$D,$A15,'All Comments'!$G:$G,"Major") -> 5 | F15: =COUNTIFS('All Comments'!$D:$D,$A15,'All Comments'!$M:$M,"Yes") -> 12 | G15: =D15-COUNTIFS('All Comments'!$D:$D,$A15,'All Comments'!$P:$P,"Done")-COUNTIFS('All Comments'!$D:$D,$A15,'All Comments'!$P:$P,"Will not change") -> 12
A16: Total | B16: =SUM(B5:B15) -> 10 | C16: =SUM(C5:C15) -> 35 | D16: =SUM(D5:D15) -> 45 | E16: =SUM(E5:E15) -> 26 | F16: =SUM(F5:F15) -> 18 | G16: =SUM(G5:G15) -> 45
A18: By theme
A19: Theme | B19: Reviewer 4 | C19: Reviewer 5 | D19: Total | E19: Major
A20: Case study value | B20: =COUNTIFS('All Comments'!$F:$F,$A20,'All Comments'!$B:$B,"Reviewer 4") -> 1 | C20: =COUNTIFS('All Comments'!$F:$F,$A20,'All Comments'!$B:$B,"Reviewer 5") -> 2 | D20: =B20+C20 -> 3 | E20: =COUNTIFS('All Comments'!$F:$F,$A20,'All Comments'!$G:$G,"Major") -> 3
A21: Code correctness | B21: =COUNTIFS('All Comments'!$F:$F,$A21,'All Comments'!$B:$B,"Reviewer 4") -> 2 | C21: =COUNTIFS('All Comments'!$F:$F,$A21,'All Comments'!$B:$B,"Reviewer 5") -> 4 | D21: =B21+C21 -> 6 | E21: =COUNTIFS('All Comments'!$F:$F,$A21,'All Comments'!$G:$G,"Major") -> 4
A22: Code quality | B22: =COUNTIFS('All Comments'!$F:$F,$A22,'All Comments'!$B:$B,"Reviewer 4") -> 1 | C22: =COUNTIFS('All Comments'!$F:$F,$A22,'All Comments'!$B:$B,"Reviewer 5") -> 3 | D22: =B22+C22 -> 4 | E22: =COUNTIFS('All Comments'!$F:$F,$A22,'All Comments'!$G:$G,"Major") -> 0
A23: Contribution | B23: =COUNTIFS('All Comments'!$F:$F,$A23,'All Comments'!$B:$B,"Reviewer 4") -> 1 | C23: =COUNTIFS('All Comments'!$F:$F,$A23,'All Comments'!$B:$B,"Reviewer 5") -> 2 | D23: =B23+C23 -> 3 | E23: =COUNTIFS('All Comments'!$F:$F,$A23,'All Comments'!$G:$G,"Major") -> 3
A24: Documentation | B24: =COUNTIFS('All Comments'!$F:$F,$A24,'All Comments'!$B:$B,"Reviewer 4") -> 0 | C24: =COUNTIFS('All Comments'!$F:$F,$A24,'All Comments'!$B:$B,"Reviewer 5") -> 1 | D24: =B24+C24 -> 1 | E24: =COUNTIFS('All Comments'!$F:$F,$A24,'All Comments'!$G:$G,"Major") -> 1
A25: Evaluation measures | B25: =COUNTIFS('All Comments'!$F:$F,$A25,'All Comments'!$B:$B,"Reviewer 4") -> 0 | C25: =COUNTIFS('All Comments'!$F:$F,$A25,'All Comments'!$B:$B,"Reviewer 5") -> 2 | D25: =B25+C25 -> 2 | E25: =COUNTIFS('All Comments'!$F:$F,$A25,'All Comments'!$G:$G,"Major") -> 0
A26: Formatting | B26: =COUNTIFS('All Comments'!$F:$F,$A26,'All Comments'!$B:$B,"Reviewer 4") -> 0 | C26: =COUNTIFS('All Comments'!$F:$F,$A26,'All Comments'!$B:$B,"Reviewer 5") -> 1 | D26: =B26+C26 -> 1 | E26: =COUNTIFS('All Comments'!$F:$F,$A26,'All Comments'!$G:$G,"Major") -> 0
A27: GPA method | B27: =COUNTIFS('All Comments'!$F:$F,$A27,'All Comments'!$B:$B,"Reviewer 4") -> 2 | C27: =COUNTIFS('All Comments'!$F:$F,$A27,'All Comments'!$B:$B,"Reviewer 5") -> 3 | D27: =B27+C27 -> 5 | E27: =COUNTIFS('All Comments'!$F:$F,$A27,'All Comments'!$G:$G,"Major") -> 5
A28: Input checks | B28: =COUNTIFS('All Comments'!$F:$F,$A28,'All Comments'!$B:$B,"Reviewer 4") -> 0 | C28: =COUNTIFS('All Comments'!$F:$F,$A28,'All Comments'!$B:$B,"Reviewer 5") -> 2 | D28: =B28+C28 -> 2 | E28: =COUNTIFS('All Comments'!$F:$F,$A28,'All Comments'!$G:$G,"Major") -> 1
A29: Interpretation | B29: =COUNTIFS('All Comments'!$F:$F,$A29,'All Comments'!$B:$B,"Reviewer 4") -> 0 | C29: =COUNTIFS('All Comments'!$F:$F,$A29,'All Comments'!$B:$B,"Reviewer 5") -> 4 | D29: =B29+C29 -> 4 | E29: =COUNTIFS('All Comments'!$F:$F,$A29,'All Comments'!$G:$G,"Major") -> 3
A30: Motivation | B30: =COUNTIFS('All Comments'!$F:$F,$A30,'All Comments'!$B:$B,"Reviewer 4") -> 0 | C30: =COUNTIFS('All Comments'!$F:$F,$A30,'All Comments'!$B:$B,"Reviewer 5") -> 3 | D30: =B30+C30 -> 3 | E30: =COUNTIFS('All Comments'!$F:$F,$A30,'All Comments'!$G:$G,"Major") -> 3
A31: Naming and API | B31: =COUNTIFS('All Comments'!$F:$F,$A31,'All Comments'!$B:$B,"Reviewer 4") -> 1 | C31: =COUNTIFS('All Comments'!$F:$F,$A31,'All Comments'!$B:$B,"Reviewer 5") -> 1 | D31: =B31+C31 -> 2 | E31: =COUNTIFS('All Comments'!$F:$F,$A31,'All Comments'!$G:$G,"Major") -> 0
... A36: Wording | B36: =COUNTIFS('All Comments'!$F:$F,$A36,'All Comments'!$B:$B,"Reviewer 4") -> 0 | C36: =COUNTIFS('All Comments'!$F:$F,$A36,'All Comments'!$B:$B,"Reviewer 5") -> 1 | D36: =B36+C36 -> 1 | E36: =COUNTIFS('All Comments'!$F:$F,$A36,'All Comments'!$G:$G,"Major") -> 0
A38: Reviewer recommendations
A39: Reviewer | B39: Overall view
A40: Reviewer 4 | B40: Contribution not substantial enough for the R Journal (leans to reject).
A41: Reviewer 5 | B41: Idea is useful and the fixed frame is sound. Substantial revision required.
A43: Figure key: reviewer figure numbers in the submitted version
A44: Reviewer reference | B44: Figure in submitted version | C44: Content
A45: R4: Figure 7 | B45: Figure 7 (fig:moveplot-plot2) | C45: moveplot2() facets, no alignment
A46: R4: Figure 8 | B46: Figure 8 (fig:moveplot3-facet-plot) | C46: moveplot3() facets, consensus target
A47: R5: Figure 9 | B47: Figure 9 (fig:fit-line-plot) | C47: PS and CC fit measures over time

Sheet All Comments
A1: ID | B1: Reviewer | C1: Reviewer item | D1: Paper section | E1: Location (submitted version) | F1: Theme | G1: Priority | H1: Comment (summary) | I1: Reviewer text (verbatim) | J1: Requested action | K1: Also raised in | L1: Check against submitted version | M1: Package change needed | N1: Package file / function | O1: Author response | P1: Status
A2: R4-01 | B2: Reviewer 4 | C2: General 1 | D2: 6 Automated alignment | E2: Figures 7 and 8 (moveplot2() facets and moveplot3() consensus facets) | F2: Case study value | G2: Major | H2: The examples show what the code does. They do not show why the output is useful. The reviewer could not find a clear finding in Figures 7 and 8. | I2: 1. The data examples in the paper demonstrate the functionality of the code, but they do not strongly motivate the code. What should a reader take away from Figures 7 and 8, from a substantive point of view? The manuscript would be much stronger if it invested in explaining the value of these visualizations to the reader, rather than leaving the reader to interpret the figures on their own. I personally struggled to find substantive takeaways from the figures. | J2: State what the reader must learn from each figure. Give the substantive result. | K2: R5-15, R5-16 | L2: Open. Figure 7 text only shows a reflection. Figure 8 text only says the biplots are consistently oriented. No substantive finding is given. The 1989 target demo (6.2) has no figure. | M2: No | P2: To do
A3: R4-02 | B3: Reviewer 4 | C3: General 2 | D3: 6 Automated alignment | E3: 6.1 Generalized Procrustes analysis | F3: GPA method | G3: Major | H3: There is no formal math for GPA. So it is hard to know what moveplot3() shows. | I3: 2. The manuscript lacks a formal mathematical description of Generalized Procrustes Analysis, which is used to produce the figures from moveplot3(). This makes it difficult to understand what is actually being visualized. | J3: Add the GPA equations: the objective, the transformations, and the iteration. | K3: R5-09 | L3: Open. Section 6.1 is one paragraph with no equations. | M3: No | P3: To do
A4: R4-03 | B4: Reviewer 4 | C4: General 3 | D4: 6 Automated alignment | E4: 6.1 and target argument | F4: GPA method | G4: Major | H4: The paper does not say why a consensus GPA target is correct. The aligned result may not keep the PCA meaning of the axes. A tensor method may give a clear shared subspace. If the subspace does not matter, one Procrustes step to any target is enough. | I4: 3. It is reasonable to want to align various principal component analyses. However, the manuscript takes as given that these various decompositions should be aligned relative to a consensus GPA alignment. Is there any particular reason for this? Does the consensus GPA alignment preserve the principal component analysis interpretation of the axes, or is this a new kind of object that must be interpreted differently (I suspect it is the latter)? Methodologically, it could make more sense to use a tensor decomposition method that embeds the various slices into a directly interpretable subspace. Alternatively, if the embedding subspace is immaterial, generalized Procrustes analysis is computationally unnecessary and a single alignment step to any target is sufficient for comparability. | J4: Justify the consensus target. Say if the aligned axes keep a PCA meaning. Discuss tensor methods and a single-step alignment. | K4: R5-04, R5-05, R5-06 | L4: Open. Section 6.1 says the target is the average, but gives no reason. | M4: Maybe | N4: moveplot3(): option for single-step alignment to one target | P4: To do
A5: R4-04 | B5: Reviewer 4 | C5: General 4 | D5: 7 Evaluation | E5: evaluation(); Section 7.1 measures | F5: Code correctness | G5: Major | H5: MB is always zero because abs() is missing. X.new is not used. AMB, MB and RMSB use the target and the unrotated, unscaled testee. PS uses the rotated one. | I5: 4. In evaluation, MB is definitionally zero due to a missing abs(). Further, in evaluation() X.new isnever used. AMB, MB, and RMSB are all computed from target - testee, where testee is the un-rotated, un-scaled configuration. Is this intended? PS, by contrast, does use the rotated configuration. | J5: Fix MB. Decide which configuration each measure must use and make them consistent. | K5: R5-C02 | L5: Open. Table 3 shows MB = 0.0000 for both years, and Section 7.4 says MB stays close to zero. Also: Section 7.3 says the target is 1989, but the code uses target = NULL. | M5: Yes | N5: evaluation() in evaluation_func.R | P5: To do
A6: R4-05 | B6: Reviewer 4 | C6: Code 1 | D6: 3 The moveEZ framework | E6: moveplot(), moveplot2(), moveplot3() | F6: Naming and API | G6: Minor | H6: The function names do not tell what each function does. | I6: 1. The names moveplot(), moveplot2(), and moveplot3() are not informative about what the functions do. | J6: Give the functions descriptive names (aliases can keep old names). | K6: R5-19 | L6: Open. Same names in Table 1 and in all sections. | M6: Yes | N6: NAMESPACE; plot.R (function names, aliases) | P6: To do
A7: R4-06 | B7: Reviewer 4 | C7: Code 2 | D7: Package code | E7: evaluation() | F7: Code correctness | G7: Minor | H7: evaluation() calls print() for a wrong input class. stop() is the usual choice. | I7: 2. When given anything other than a moveplot3 object, evaluation() calls print(). stop() would be the conventional choice here. | J7: Use stop() with a clear message. | L7: Open. Paper link: the Conclusion says evaluation() works with all three functions, but the code accepts only moveplot3() objects. | M7: Yes | N7: evaluation() in evaluation_func.R | P7: To do
A8: R4-07 | B8: Reviewer 4 | C8: Code 3 | D8: Package code | E8: evaluation(): Tot.SS, Fit.SS, n.X, p.X, p.Y, X.new | F8: Code quality | G8: Minor | H8: Some objects are calculated but not used. | I8: 3. In evaluation(), Tot.SS, Fit.SS, n.X, p.X, and p.Y are computed but never used, and X.new is computed but never used. Is this intended? | J8: Remove them or use them. | K8: R5-C02, R5-C07 | L8: Package only. Not visible in the paper. | M8: Yes | N8: evaluation() in evaluation_func.R | P8: To do
A9: R4-08 | B9: Reviewer 4 | C9: Typo 1 | D9: 4 Fixed variable frame | E9: Section 4.2, sentence after Figure 4 | F9: Typo | G9: Minor | H9: Typo: "are are". | I9: • pg. 8: “These aspects are are addressed in moveEZ.” | J9: Remove the repeated word. | K9: R5-21 | L9: Still in submitted version (Section 4.2). | M9: No | P9: To do
A10: R4-09 | B10: Reviewer 4 | C10: Typo 2 | D10: 6 Automated alignment | E10: Section 6.1 | F10: Typo | G10: Minor | H10: Wording "squared sum of squares distances" is not correct. | I10: • pg. 11: “the squared sum of squares distances” | J10: Rewrite the phrase. | K10: R5-09 | L10: Still in submitted version (Section 6.1). | M10: Maybe | N10: moveplot3() help page (if same wording) | P10: To do
A11: R4-10 | B11: Reviewer 4 | C11: Summary | D11: Whole paper | E11: Whole paper | F11: Contribution | G11: Major | H11: The contribution is not large enough for the R Journal. GPA is well known and easy to code. Animation is ggplot2 plus gganimate. The wrapper adds little. Method choices are not justified, so the figures are ambiguous. | I11: [From 1. General:] moveEZ is an R package that animates PCA biplots, constructing biplots with biplotEZ and animating them with gganimate. The key idea is that some data has a time dimension, and so one might want to animate a PCA biplot over time. moveEZ exposes three plotting functions and one diagnostic function: • moveplot(): embed data from all time points into the same shared subspace, • moveplot2(): embed data from all time points into distinct subspaces of the same dimension, leaving the user to align them via the align.time and reflect arguments, • moveplot3(): embed data from all time points into distinct subspaces of the same dimension, and then align them automatically by generalized Procrustes analysis (GPA), and • evaluation(): report Procrustes-based measures comparing each aligned time slice against the target configuration. The paper is clearly written and easy to follow. The package installs cleanly and the worked examples run. [From 5. Summary:] My view is that the contribution is not substantial in the sense the R Journal requires. The alignment step is a well-known technique that is straightforward to implement (see below) and once the data has been aligned, animating the biplots is a straightforward combination of ggplot2 and gganimate. [R code from the report:] library(gapminder) library(vegan) pca_vars <- c("lifeExp", "gdpPercap", "pop") years <- sort(unique(gapminder$year)) # scale once globally scaled_vars <- scale(gapminder[pca_vars]) # one PCA score matrix per year, aligned by country so that row i always # refers to the same country -- GPA/Procrustes requires the rows of each # configuration to correspond to the same entities configs <- lapply(years, function(yr) { rows <- gapminder$year == yr by_country <- order(gapminder$country[rows]) prcomp(scaled_vars[rows, ][by_country, ])$x }) # --- generalized Procrustes analysis --------------------------------- # Start from one year as an initial guess at the consensus shape, then # iterate: align every year to the current consensus, recompute the # consensus as the mean of the aligned configurations, and repeat until # the consensus stops moving. consensus <- configs[[1]] repeat { aligned <- lapply(configs, function(cfg) procrustes(X = consensus, Y = cfg)$Yrot) new_consensus <- Reduce(`+`, aligned) / length(aligned) shift <- sqrt(sum((new_consensus - consensus)^2)) consensus <- new_consensus if (shift < 1e-8) break } aligned_by_year <- setNames(aligned, years) It may be true that this functionality has not been cleanly wrapped into a single function before, but the convenience of a wrapper around this functionality is quite modest. Further, the manuscript does not justify its methodological choices in terms of any properties of generalized Procrustes analysis or common variance structures or shared subspaces, so the interpretation of the figures produced by moveEZ is ambiguous. | J11: Make the case for the contribution. Justify the method choices with properties of GPA or shared subspaces. | K11: R5-13 | L11: Open. The Conclusion claims a gap in the R ecosystem with no comparison to other packages. | M11: No | P11: To do
A12: R5-01 | B12: Reviewer 5 | C12: General | D12: Whole paper | E12: Whole paper | F12: Contribution | G12: Major | H12: moveplot() with a fixed frame is sound and useful. The dynamic frame (moveplot2(), moveplot3()) lacks justification, validation, links to other work, and clear presentation. Needs a large revision. | I12: The `moveEZ` package addresses a potentially useful problem: animating PCA biplots across the levels of an ordered categorical variable. The `moveplot()` function, which projects observations from different time slices into a common global PCA space, is conceptually sound and represents a reasonable contribution to the R community. In particular, the use of a fixed variable frame provides an intuitive way to examine trajectories in multivariate data while maintaining a stable coordinate system. However, the manuscript has substantial weaknesses in methodological justification, validation, literature engagement, and presentation. In particular, the statistical motivation and interpretation of the dynamic variable frame implemented by `moveplot2()` and `moveplot3()` are not sufficiently established. The manuscript currently treats the alignment of separately computed PCA solutions primarily as a technical visualization problem, whereas it raises more fundamental questions about whether the resulting components and variable vectors are statistically comparable across time. The manuscript also does not adequately position `moveEZ` relative to the existing ecosystem of animated high-dimensional visualization in R, particularly tour methods. Overall, I think the underlying idea is potentially useful, and the fixed-frame approach is sensible. However, substantial revision is required before the manuscript can be considered for publication. | J12: Address points R5-02 to R5-25 and the code points. | K12: R4-10 | L12: Open. | M12: No | P12: To do
A13: R5-02 | B13: Reviewer 5 | C13: 1 | D13: 5 Dynamic frame | E13: Section 3 text; Table 1; Section 5 | F13: Motivation | G13: Major | H13: It is not clear when a separate PCA per time point is necessary. Reviewer asks four questions: which question needs it, what it adds over moveplot() or static plots, when to use a fixed frame, and how to check that PC1 and PC2 show the temporal structure. | I13: The fixed-frame approach in `moveplot()` is relatively straightforward to interpret because observations are projected into a common PCA space. The motivation for changing the variable frame in `moveplot2()` and `moveplot3()` is less clear. The authors should identify the specific analytical questions for which a separate PCA at each time point is necessary or substantially more informative than a fixed global PCA or a sequence of static PCA plots. In particular, they should explain: 1. What substantive question requires a separate PCA at each time point? 2. What information is gained that cannot be obtained from `moveplot()` or static PCA plots? 3. When should users prefer a fixed frame over a dynamic frame? 4. How should users assess whether PC1 and PC2 adequately represent the relevant temporal structure? | J13: Answer the four questions in the paper. | K13: R4-03 | L13: Partly. Section 3 and Table 1 say when to use each function. The four questions are not answered. | M13: Maybe | N13: Vignette and help pages (choice guidance) | P13: To do
A14: R5-03 | B14: Reviewer 5 | C14: 1 | D14: 2 PCA Biplots | E14: First two PCs | F14: Motivation | G14: Major | H14: Only PC1 and PC2 are shown. Change over time can occur in higher PCs. Tours can use all dimensions. | I14: The restriction to the first two PCs also needs justification. Important temporal variation may occur in higher-order components and therefore be missed by a two-dimensional representation. This is particularly relevant when comparing `moveEZ` with tour methods, which can explore projections involving all dimensions. The authors should discuss this limitation and provide practical guidance on when a PC1–PC2 representation is appropriate. | J14: Justify the two-PC limit. Give guidance on when it is sufficient. | K14: R5-11 | L14: Open. Section 2 uses only the first two columns. No discussion of other PCs. | M14: Maybe | N14: moveplot functions: option to pick other PCs | P14: To do
A15: R5-04 | B15: Reviewer 5 | C15: 1 | D15: 5 Dynamic frame | E15: Section 5 | F15: Motivation | G15: Major | H15: The purpose of the dynamic frame is not stated. If it is to show how variable directions change, say so. | I15: The authors should also clarify the relationship between the dynamic frame and the underlying analytical objective. If the primary purpose is to examine how variable directions change over time, this should be stated explicitly, together with guidance on when such changes are substantively meaningful rather than simply a consequence of refitting PCA. | J15: State the goal. Tell users when direction changes are real and not only an effect of refitting PCA. | K15: R4-03 | L15: Open. Section 5 says the dynamic frame is "more faithful" but gives no guidance. | M15: No | P15: To do
A16: R5-05 | B16: Reviewer 5 | C16: 2 | D16: 6 Automated alignment | E16: Sections 5 and 6 | F16: GPA method | G16: Major | H16: If the covariance changes, separate PCAs can point in different directions. It is not clear what it means to align them. A rotating vector can mean a change in importance, a change in relations, or an unstable PCA. | I16: The main concern is the statistical interpretation of `moveplot2()` and `moveplot3()`. The manuscript argues that these functions are useful when directional relationships among variables evolve over time. However, if the variance-covariance structure changes across time slices, separately computed PCA solutions may represent different directions in variable space at different time points. This raises an important issue beyond simply aligning the plots. The authors should clarify what it means statistically to align PC1 and PC2 when these components may represent substantially different directions at different time points. Similarly, when a variable vector rotates, does this reflect a change in variable importance, relationships among variables, or instability in the separately estimated PCA solution? These possibilities should be distinguished rather than treating rotation as inherently meaningful temporal evolution. | J16: Explain what alignment means statistically. Separate the three causes of rotation. | K16: R4-03 | L16: Open. | M16: No | P16: To do
A17: R5-06 | B17: Reviewer 5 | C17: 2 | D17: 5 Dynamic frame | E17: Sections 5 and 6 | F17: Interpretation | G17: Major | H17: Each slice has its own coordinate system. Alignment makes plots look similar but does not make the axes equal. Changes in point position or hull spread can come from the PCA or total variance, not the data. | I17: The interpretation of point positions and spread across frames also requires clarification. Because PCA is refitted for each subset, each biplot is initially defined in a different coordinate system. Although the alignment procedure attempts to make these configurations visually comparable, it does not necessarily make the PC axes statistically equivalent. Consequently, changes in the positions or spread of points and hulls may reflect changes in the PCA solution or total variance rather than changes in the observations themselves. This differs from a typical tour, where the data remain fixed and the projection basis changes while preserving the underlying data geometry. In the proposed approach, PCA is refitted at each time slice and GPA may additionally allow scaling. If total variance differs across time slices, this scaling may obscure genuine changes in the magnitude of variation. The authors should clarify this distinction and discuss its implications for interpretation. | J17: Discuss this. Compare with tours, where the data stay fixed. | K17: R5-12 | L17: Open. | M17: No | P17: To do
A18: R5-07 | B18: Reviewer 5 | C18: 2 | D18: 6 Automated alignment | E18: 6.1; moveplot3() | F18: GPA method | G18: Major | H18: It is not stated if GPA scaling is on. Scaling can hide real changes in total variance. | I18: The use of Generalized Procrustes Analysis (GPA) also requires clarification. In particular, the authors should state whether scaling is enabled in `moveplot3()`. If scaling is applied, it may alter the relative magnitudes of the components and hence the representation of the variance structure. If scaling is disabled, the authors should explain why the remaining transformations are appropriate. | J18: State if scaling is on. Explain the effect, or explain why the other transformations are enough. | K18: R5-C01 | L18: Open. Section 6.1 says scaling is applied. It also says the transformations preserve distances, which is not true when scaling is used. | M18: Yes | N18: moveplot3() in plot.R: scaling argument | P18: To do
A19: R5-08 | B19: Reviewer 5 | C19: 2 | D19: 6 Automated alignment | E19: New content | F19: Validation | G19: Major | H19: Smaller distances do not prove the PCAs are comparable. | I19: More fundamentally, minimizing distances between configurations does not establish that the resulting PCA solutions are statistically comparable. Simulation studies with a known time-varying covariance structure would substantially strengthen the manuscript by assessing whether the proposed alignment recovers known changes or can itself introduce apparent rotations. | J19: Add a simulation with a known time-varying covariance. Test if alignment finds true changes or makes false rotations. | L19: Open. No simulation in the paper. | M19: No | P19: To do
A20: R5-09 | B20: Reviewer 5 | C20: 2 | D20: 6 Automated alignment | E20: 6.1 criterion sentence | F20: GPA method | G20: Major | H20: The alignment criterion is not clear. It does not define the distance between biplots. | I20: The description of the alignment criterion, that the "squared sum of squares distances between a set target biplot and the aligned biplots are minimized", is also insufficiently clear. The authors should define what constitutes a distance between biplots and how these distances are computed, rather than relying solely on the cited reference. | J20: Define the distance and how it is calculated in the paper. | K20: R4-02, R4-09 | L20: Open. Section 6.1 only cites a reference. | M20: No | P20: To do
A21: R5-10 | B21: Reviewer 5 | C21: 2 | D21: 5 Dynamic frame | E21: Sections 4, 5 and 6 | F21: Interpretation | G21: Major | H21: Users need guidance on how to read movement. For moveplot(), movement is in a fixed space. For moveplot2() and moveplot3(), the moving frame adds ambiguity. | I21: I can see value in using this approach to examine how variable directions change over time, similar in spirit to a tour. However, interpreting changes in the positions or spread of points and hulls is more difficult when both the PCA directions and total variance vary across time. This limitation should be explicitly acknowledged. Finally, the manuscript should provide clearer guidance on interpreting movement in the biplots. For `moveplot()`, this involves explaining movement within a fixed PCA space relative to the variable vectors; for `moveplot2()` and `moveplot3()`, the additional ambiguity caused by the changing coordinate system should be explicitly discussed. | J21: Say this limit clearly. Give reading guidance for each function. | K21: R5-06 | L21: Open. | M21: Maybe | N21: Vignette and help pages (reading guidance) | P21: To do
A22: R5-11 | B22: Reviewer 5 | C22: 3 | D22: 1 Introduction | E22: Introduction; related work | F22: Related work | G22: Major | H22: The paper does not compare moveEZ with tourr, spinifex, langevitour and detourr. | I22: The manuscript needs a stronger discussion of existing approaches to animated high-dimensional visualization, particularly within the R ecosystem. The authors should position `moveEZ` relative to established packages such as `tourr`, `spinifex`, `langevitour`, and `detourr`, explaining what analytical questions `moveEZ` addresses that these approaches do not. | J22: Add a related work part. Say what moveEZ does that these do not. | K22: R5-03 | L22: Open. No tour packages are cited. | M22: No | P22: To do
A23: R5-12 | B23: Reviewer 5 | C23: 3 | D23: 1 Introduction | E23: Introduction | F23: Related work | G23: Major | H23: Tours keep the data fixed and move the projection. moveEZ refits PCA and can rescale. | I23: In particular, the authors should clarify how the repeated PCA/GPA procedure differs conceptually from tour methods. In a typical tour, the data remain fixed while the projection basis changes continuously, whereas the proposed approach refits the PCA solution at each time point and may additionally rescale the configurations. The implications of this difference for statistical interpretation should be made explicit. | J23: Explain this difference and what it means for interpretation. | K23: R5-06 | L23: Open. | M23: No | P23: To do
A24: R5-13 | B24: Reviewer 5 | C24: 3 | D24: 1 Introduction | E24: Introduction | F24: Contribution | G24: Major | H24: It is not clear if animated biplots over an ordered variable are new. | I24: The manuscript should also clarify whether animating biplots across an ordered variable is novel, or more specifically, how the implementation and statistical methodology differ from previous approaches. This would help establish the methodological contribution beyond the provision of a new R package. | J24: State the novelty. Compare with earlier methods. | K24: R4-10 | L24: Open. | M24: No | P24: To do
A25: R5-14 | B25: Reviewer 5 | C25: 3 | D25: 1 Introduction | E25: Introduction claims on animation | F25: Related work | G25: Minor | H25: Claims that animation helps people see movement have no support. | I25: Finally, claims about the benefits of animation for perceiving multivariate movement should be supported by relevant literature on animated statistical graphics and visual perception, including discussion of their limitations. | J25: Cite work on animated graphics and perception, with its limits. | L25: Open. The Introduction claim about seeing continuous movement has no citation. | M25: No | P25: To do
A26: R5-15 | B26: Reviewer 5 | C26: 4 | D26: 4 Fixed variable frame | E26: Sections 4.2, 5, 6; Figures 4, 5, 7, 8 | F26: Case study value | G26: Major | H26: The Africa climate example shows function, not analytical value. | I26: The Africa climate example is potentially useful, but it currently demonstrates functionality more than substantive analytical value. The authors should state the specific analytical question being addressed and explain what is learned from the animation that would be difficult to identify from static PCA plots, a fixed-frame `moveplot()`, or existing visualization methods. | J26: State the question. Show what the animation shows that static plots or moveplot() do not. | K26: R4-01 | L26: Open. Section 4.2 says moveEZ addresses the limits of Figure 4, but no finding from Figure 5 is given. | M26: No | P26: To do
A27: R5-16 | B27: Reviewer 5 | C27: 4 | D27: 4 Fixed variable frame | E27: Sections 4.2, 5, 6; Figures 4, 5, 7, 8 | F27: Case study value | G27: Major | H27: The example needs a concrete temporal finding. | I27: A stronger case study should demonstrate a concrete temporal pattern or substantive insight revealed by the dynamic biplot. For example, the authors could identify a change in the relationships among variables over time and show how this change is revealed by the dynamic variable frame. | J27: Show, for example, a change in variable relations that the dynamic frame reveals. | K27: R4-01 | L27: Open. | M27: No | P27: To do
A28: R5-17 | B28: Reviewer 5 | C28: 4 | D28: 4 Fixed variable frame | E28: Sections 4.2, 5, 6; Figures 4, 5, 7, 8 | F28: Interpretation | G28: Major | H28: It is not clear what causes the movement: the data, the PCA basis, the total variance, or a mix. | I28: The case study should also make clear whether the observed movement reflects changes in the underlying data, changes in the PCA basis, changes in total variance, or some combination of these. This would provide a more convincing demonstration of the analytical value of the proposed approach rather than simply showing that the functions can produce an animation. | J28: Separate these causes in the case study. | K28: R5-06 | L28: Open. | M28: No | P28: To do
A29: R5-18 | B29: Reviewer 5 | C29: 5 (Sec 3) | D29: 3 The moveEZ framework | E29: Section 3, first paragraph | F29: Wording | G29: Minor | H29: The claim that linear easing makes movement interpretable is too strong. Smooth is not the same as interpretable. | I29: * The statement that “Linear easing produces transitions at a constant rate, ensuring smooth and visually interpretable movement between states” may be too strong. Constant-rate interpolation produces smooth visual transitions, but smoothness does not necessarily imply statistical interpretability. The authors should qualify this statement. | J29: Qualify the sentence. | L29: Still in submitted version. | M29: No | P29: To do
A30: R5-19 | B30: Reviewer 5 | C30: 5 (Sec 3) | D30: 3 The moveEZ framework | E30: Function names | F30: Naming and API | G30: Minor | H30: The function names do not show how the methods differ. | I30: * The function names `moveplot()`, `moveplot2()`, and `moveplot3()` are not particularly informative about the methodological differences between the functions. More descriptive names would make the package easier to understand and use. | J30: Use descriptive names. | K30: R4-05 | L30: Open. | M30: Yes | N30: NAMESPACE; plot.R (function names, aliases) | P30: To do
A31: R5-20 | B31: Reviewer 5 | C31: 5 (Sec 4) | D31: 4 Fixed variable frame | E31: Section 4.1, text after Figure 3 | F31: Interpretation | G31: Minor | H31: The paper says population adds less information because of its large variance. But the data are scaled, so this reason is wrong. The population vector also looks long and on one PC. | I31: * The statement that population provides “less discriminatory information in the PCA space due to its large variance” requires clarification. Since PCA is performed with `scaled = TRUE`, the variables are standardized before PCA, so the larger original variance of population should not explain its contribution. Moreover, the population vector appears relatively long and strongly aligned with one of the principal components, along which Asia shows substantial movement. Please clarify how the authors infer that population contributes less discriminatory information from the vector orientations. | J31: Correct or explain the statement. | L31: Still in submitted version. The text also adds "This is confirmed by the vector orientation", which the reviewer questions. | M31: No | P31: To do
A32: R5-21 | B32: Reviewer 5 | C32: 5 (Sec 4) | D32: 4 Fixed variable frame | E32: Section 4.2, sentence after Figure 4 | F32: Typo | G32: Minor | H32: Typo: "are are". | I32: * There is a grammatical error: “are are” should be corrected to “are.” | J32: Remove the repeated word. | K32: R4-08 | L32: Still in submitted version (Section 4.2). | M32: No | P32: To do
A33: R5-22 | B33: Reviewer 5 | C33: 5 (Sec 4) | D33: 4 Fixed variable frame | E33: hulls argument; move = FALSE | F33: Visual design | G33: Minor | H33: Convex hulls are sensitive to outliers. | I33: * When `move = FALSE`, convex hulls are used to summarize each region at each time point. Convex hulls can be strongly influenced by outliers and may therefore give a misleading representation of the central structure. Have the authors considered 90% or 95% multivariate normal ellipses, as commonly used in PCA visualizations to represent the central regions of groups? | J33: Think about 90% or 95% ellipses as an option. | L33: Open. Only the hulls argument exists. | M33: Yes | N33: plot.R: ellipse option next to hulls | P33: To do
A34: R5-23 | B34: Reviewer 5 | C34: 5 (Sec 7) | D34: 7 Evaluation | E34: 7.1 PS and CC | F34: Evaluation measures | G34: Minor | H34: It is not clear how PS and CC differ or why both are given. | I34: * The manuscript reports both the Procrustes Statistic (PS) and Congruence Coefficient (CC), with values close to zero indicating high similarity for PS and values close to one indicating high similarity for CC. How do these two measures differ, and what additional information is gained by reporting both? | J34: Explain the difference and the added value. | L34: Open. Section 7.1 lists both with no comparison. | M34: No | P34: To do
A35: R5-24 | B35: Reviewer 5 | C35: 5 (Sec 7) | D35: 7 Evaluation | E35: Figure 9 (fit plot) | F35: Evaluation measures | G35: Minor | H35: PS and CC go in opposite directions. The CC range is small. | I35: * For Figure 9, why not transform the Congruence Coefficient to `1 - CC` so that both measures have the same interpretation—where values closer to zero indicate greater similarity? This would also allow the plot to focus on the relatively small range of values shown for CC and make differences easier to see. | J35: Plot 1 - CC so both measures read the same way. | L35: Open. Figure 9 plots CC as it is. | M35: Yes | N35: evaluation(): fit.plot | P35: To do
A36: R5-25 | B36: Reviewer 5 | C36: 5 (Sec 10) | D36: 10 References | E36: References heading | F36: Formatting | G36: Minor | H36: Both "Reference" and "Bibliography" headings appear. | I36: * The manuscript contains both “Reference” and “Bibliography” headings. Only one is necessary. | J36: Keep one heading. | L36: Confirmed. The .Rmd has a "# References" heading and the R Journal template adds "Bibliography". Remove "# References". | M36: No | P36: To do
A37: R5-C00 | B37: Reviewer 5 | C37: Code: Usability | D37: Package code | E37: Docs and API | F37: Documentation | G37: Major | H37: No clear workflow to choose a function. Docs have copy-paste errors. Some examples and parameters do not match the code. | I37: The package does not provide a sufficiently clear workflow for choosing between `moveplot()`, `moveplot2()`, and `moveplot3()`. Their different purposes and statistical mechanisms should be explained more explicitly. There are also implementation inconsistencies, duplicated/dead code, fragile input handling, inconsistent treatment of sparse data, and inconsistent output structures that could confuse users or cause downstream problems. The documentation is generally user-oriented and provides useful examples, but it contains several inconsistencies and copy–paste errors that reduce confidence in the package. In particular, some examples and parameter descriptions do not match the implementation, while `evaluation()` makes assumptions about the time variable and appears inconsistent with its stated interpretation. A careful documentation and API consistency check is needed before submission. | J37: Do a full docs and API check. | K37: R5-02 | L37: Partly. Table 1 in Section 3 helps users choose. Package docs not checked (code not attached). | M37: Yes | N37: Help pages, examples, vignette | P37: To do
A38: R5-C01 | B38: Reviewer 5 | C38: Code 1 | D38: Package code | E38: plot.R:759 (s.list) | F38: Code correctness | G38: Major | H38: moveplot3() gets the GPA scale list and does not use it. Scaling depends on GPAbin defaults, which are not set or documented. | I38: 1. GPA scaling is used without being discussed or reported. `moveplot3()` pulls `s.list` out of the GPA output (`plot.R:759`) and then discards it. Whether configurations are isotropically scaled before alignment is a substantive decision: if scaling is allowed, differences in total variance between slices (spread changes, which are real signal in climate data) are normalized away before the viewer sees them. Whether that happened depends on `GPAbin::GPA` defaults, which the package neither controls explicitly nor documents. | J38: Set the scaling option in the code and document it. | K38: R5-07 | L38: Paper link: Section 6.1 says scaling is applied. Code not attached. | M38: Yes | N38: moveplot3() in plot.R:759 | P38: To do
A39: R5-C02 | B39: Reviewer 5 | C39: Code 2 | D39: Package code | E39: evaluation_func.R:71-86 | F39: Code correctness | G39: Major | H39: evaluation() fits Procrustes, but only PS uses it. CC, RMSB, MB, AMB use the raw configurations. X.new is not used. PS leaves out b.fact. | I39: 2. `evaluation()` is internally inconsistent about what it compares. The function recomputes a Procrustes fit (`C.mat`, `A.mat`, `s.fact`, `b.fact`, `X.new` — `evaluation_func.R:71-77`) but then only PS is evaluated on the aligned quantities. CC, RMSB, MB, AMB are computed on the raw, pre-alignment testee vs. target (`evaluation_func.R:83-86`). Since the whole point of `moveplot3` is that pre-alignment frames differ by arbitrary rotations/reflections, these bias measures will be dominated by alignment ambiguity rather than genuine discrepancy, and the fitted `X.new` (with its translation term) is never actually used. Either the measures are on the wrong basis, or the Procrustes block is dead code. Also note PS's residual uses `s.fact*testee%*%A.mat` without `b.fact`, inconsistent with the `X.new` definition on the same page. | J39: Put all measures on the correct basis, or remove the dead block. | K39: R4-04, R4-07 | L39: Paper link: Table 3 and Figure 10 show the values from this code. Code not attached. | M39: Yes | N39: evaluation() in evaluation_func.R:71-86 | P39: To do
A40: R5-C03 | B40: Reviewer 5 | C40: Code 3 | D40: Package code | E40: evaluation_func.R:100-106 | F40: Code correctness | G40: Major | H40: "Year" is hard-coded. Other time names give wrong labels. Non-numeric levels become NA. | I40: 3. Hard-coded "Year". `evaluation()` extracts the time label with `gsub("Target vs. ", ...)` and builds a `Year` column (`evaluation_func.R:100-106`). With any other time variable name the axis label is wrong, and non-numeric levels silently become NA. The package advertises an arbitrary ordered index; this is a latent bug. | J40: Use the user's time variable name and allow non-numeric levels. | L40: Paper link: Table 3 headers "Target vs. 1950" come from this code. Code not attached. | M40: Yes | N40: evaluation() in evaluation_func.R:100-106 | P40: To do
...

Sheet Package Changes
A1: Changes to the moveEZ package (from all comments with Package change needed = Yes or Maybe)
A2: Status is a formula that reads the All Comments sheet. Update the status there.
A4: ID | B4: Package file / function | C4: Needed | D4: Priority | E4: Requested action | F4: Also raised in | G4: Status
A5: R5-C06 | B5: All moveplot functions: input checks | C5: Yes | D5: Minor | E5: Validate inputs and give clear messages. Document NA handling. | G5: =INDEX('All Comments'!$P:$P,MATCH($A5,'All Comments'!$A:$A,0)) -> To do
A6: R5-C08 | B6: DESCRIPTION; plot.R:446; evaluation_func.R:110 | C6: Yes | D6: Minor | E6: Move them to Imports or add checks. | G6: =INDEX('All Comments'!$P:$P,MATCH($A6,'All Comments'!$A:$A,0)) -> To do
A7: R5-C00 | B7: Help pages, examples, vignette | C7: Yes | D7: Major | E7: Do a full docs and API check. | F7: R5-02 | G7: =INDEX('All Comments'!$P:$P,MATCH($A7,'All Comments'!$A:$A,0)) -> To do
A8: R4-05 | B8: NAMESPACE; plot.R (function names, aliases) | C8: Yes | D8: Minor | E8: Give the functions descriptive names (aliases can keep old names). | F8: R5-19 | G8: =INDEX('All Comments'!$P:$P,MATCH($A8,'All Comments'!$A:$A,0)) -> To do
A9: R5-19 | B9: NAMESPACE; plot.R (function names, aliases) | C9: Yes | D9: Minor | E9: Use descriptive names. | F9: R4-05 | G9: =INDEX('All Comments'!$P:$P,MATCH($A9,'All Comments'!$A:$A,0)) -> To do
A10: R4-04 | B10: evaluation() in evaluation_func.R | C10: Yes | D10: Major | E10: Fix MB. Decide which configuration each measure must use and make them consistent. | F10: R5-C02 | G10: =INDEX('All Comments'!$P:$P,MATCH($A10,'All Comments'!$A:$A,0)) -> To do
A11: R4-06 | B11: evaluation() in evaluation_func.R | C11: Yes | D11: Minor | E11: Use stop() with a clear message. | G11: =INDEX('All Comments'!$P:$P,MATCH($A11,'All Comments'!$A:$A,0)) -> To do
A12: R4-07 | B12: evaluation() in evaluation_func.R | C12: Yes | D12: Minor | E12: Remove them or use them. | F12: R5-C02, R5-C07 | G12: =INDEX('All Comments'!$P:$P,MATCH($A12,'All Comments'!$A:$A,0)) -> To do
A13: R5-C03 | B13: evaluation() in evaluation_func.R:100-106 | C13: Yes | D13: Major | E13: Use the user's time variable name and allow non-numeric levels. | G13: =INDEX('All Comments'!$P:$P,MATCH($A13,'All Comments'!$A:$A,0)) -> To do
A14: R5-C02 | B14: evaluation() in evaluation_func.R:71-86 | C14: Yes | D14: Major | E14: Put all measures on the correct basis, or remove the dead block. | F14: R4-04, R4-07 | G14: =INDEX('All Comments'!$P:$P,MATCH($A14,'All Comments'!$A:$A,0)) -> To do
A15: R5-24 | B15: evaluation(): fit.plot | C15: Yes | D15: Minor | E15: Plot 1 - CC so both measures read the same way. | G15: =INDEX('All Comments'!$P:$P,MATCH($A15,'All Comments'!$A:$A,0)) -> To do
A16: R5-C05 | B16: moveplot2(), moveplot3() in plot.R:500, 788 | C16: Yes | D16: Minor | E16: Add the same guard to all functions and document it. | G16: =INDEX('All Comments'!$P:$P,MATCH($A16,'All Comments'!$A:$A,0)) -> To do
A17: R5-C04 | B17: moveplot3() in plot.R: input checks before GPAbin::GPA | C17: Yes | D17: Major | E17: Check row counts and order before GPA. | G17: =INDEX('All Comments'!$P:$P,MATCH($A17,'All Comments'!$A:$A,0)) -> To do
A18: R5-07 | B18: moveplot3() in plot.R: scaling argument | C18: Yes | D18: Major | E18: State if scaling is on. Explain the effect, or explain why the other transformations are enough. | F18: R5-C01 | G18: =INDEX('All Comments'!$P:$P,MATCH($A18,'All Comments'!$A:$A,0)) -> To do
A19: R5-C01 | B19: moveplot3() in plot.R:759 | C19: Yes | D19: Major | E19: Set the scaling option in the code and document it. | F19: R5-07 | G19: =INDEX('All Comments'!$P:$P,MATCH($A19,'All Comments'!$A:$A,0)) -> To do
A20: R5-22 | B20: plot.R: ellipse option next to hulls | C20: Yes | D20: Minor | E20: Think about 90% or 95% ellipses as an option. | G20: =INDEX('All Comments'!$P:$P,MATCH($A20,'All Comments'!$A:$A,0)) -> To do
A21: R5-C07 | B21: plot.R; moveplot_func.R | C21: Yes | D21: Minor | E21: Move shared code to one helper. Remove or export moveplot_func(). | F21: R4-07 | G21: =INDEX('All Comments'!$P:$P,MATCH($A21,'All Comments'!$A:$A,0)) -> To do
A22: R5-C09 | B22: tests/ folder | C22: Yes | D22: Minor | E22: Add tests. | G22: =INDEX('All Comments'!$P:$P,MATCH($A22,'All Comments'!$A:$A,0)) -> To do
A23: R5-02 | B23: Vignette and help pages (choice guidance) | C23: Maybe | D23: Major | E23: Answer the four questions in the paper. | F23: R4-03 | G23: =INDEX('All Comments'!$P:$P,MATCH($A23,'All Comments'!$A:$A,0)) -> To do
A24: R5-10 | B24: Vignette and help pages (reading guidance) | C24: Maybe | D24: Major | E24: Say this limit clearly. Give reading guidance for each function. | F24: R5-06 | G24: =INDEX('All Comments'!$P:$P,MATCH($A24,'All Comments'!$A:$A,0)) -> To do
A25: R5-03 | B25: moveplot functions: option to pick other PCs | C25: Maybe | D25: Major | E25: Justify the two-PC limit. Give guidance on when it is sufficient. | F25: R5-11 | G25: =INDEX('All Comments'!$P:$P,MATCH($A25,'All Comments'!$A:$A,0)) -> To do
A26: R4-09 | B26: moveplot3() help page (if same wording) | C26: Maybe | D26: Minor | E26: Rewrite the phrase. | F26: R5-09 | G26: =INDEX('All Comments'!$P:$P,MATCH($A26,'All Comments'!$A:$A,0)) -> To do
A27: R4-03 | B27: moveplot3(): option for single-step alignment to one target | C27: Maybe | D27: Major | E27: Justify the consensus target. Say if the aligned axes keep a PCA meaning. Discuss tensor methods and a single-step alignment. | F27: R5-04, R5-05, R5-06 | G27: =INDEX('All Comments'!$P:$P,MATCH($A27,'All Comments'!$A:$A,0)) -> To do

Sheet Shared Themes
A1: Shared theme | B1: Reviewer 4 | C1: Reviewer 5 | D1: Paper section | E1: Why it matters
A2: Justify GPA alignment and what the aligned axes mean | B2: R4-03 | C2: R5-04, R5-05, R5-06, R5-07 | D2: 6 Automated alignment | E2: Both reviewers doubt that aligned PCAs keep a clear PCA meaning.
A3: Formal definition of GPA and its distance | B3: R4-02, R4-09 | C3: R5-09 | D3: 6 Automated alignment | E3: Both ask for a precise method description in the paper.
A4: Examples must show real findings | B4: R4-01 | C4: R5-15, R5-16, R5-17 | D4: 4 to 6 (Africa climate) | E4: Both say the figures show function, not insight.
A5: evaluation() measures use the wrong basis | B5: R4-04, R4-07 | C5: R5-C02 | D5: 7 Evaluation | E5: Both found the same code error. MB = 0.0000 in Table 3 agrees with it.
A6: Function names are not descriptive | B6: R4-05 | C6: R5-19 | D6: 3 The moveEZ framework | E6: Both ask for it. Needs a package change.
A7: Contribution and novelty | B7: R4-10 | C7: R5-01, R5-13 | D7: Whole paper | E7: Key point for the editor's decision.
A8: Typo "are are" | B8: R4-08 | C8: R5-21 | D8: 4 Fixed variable frame | E8: Still in Section 4.2 of the submitted version.
